Workbook
Name ASAT: #REF!
Name ValuationDate: [1]ValuationDate!$B$2
Name ValuationDate: ValuationDate!$B$2

Sheet Dropdown COB
A1: 01 - PROPERTY
A2: 02 - MOTOR VEHICLE
A3: 03 - MARINE CARGO
A4: 10 - GENERAL ACCIDENT
A5: VARIOUS

Sheet Instructions
A1: User Input:
B3: Sheet Name | C3: Column Name | D3: Remarks
B4: ValuationDate | C4: VALUATION DATE | D4: Tanggal valuasi
B6: Sheet Name | C6: Column Name | D6: Remarks
B7: ICG | C7: ICG | D7: Kode nama group (unique)
B8: ICG | C8: Cohort | D8: Cohort (tahun)
B9: ICG | C9: Portfolio | D9: Nama portofolio
B10: ICG | C10: Contract | D10: IC (Insurance Contracts) / RC (Reinsurance Contracts)
B12: Sheet Name | C12: Column Name | D12: Remarks
B13: Earned | C13: ICG | D13: Kode nama group
B14: Earned | C14: Incurred | D14: Tanggal akhir bulan dimana alokasi premi & komisi terjadi dibulan tersebut
B15: Earned | C15: Earned_Premium | D15: Jumlah alokasi premi
B16: Earned | C16: Earned_Commission | D16: Jumlah alokasi komisi
... B48: Assumptions | C48: NPR_Ratio | D48: Asumsi non-performance risk dari reasuradur (untuk new cohort asumsi initial = asumsi valuasi)

Sheet User Input>>

Sheet ValuationDate
A2: VALUATION DATE: | B2: 45930

Sheet ICG
A1: ICG | B1: Cohort | C1: Portfolio | D1: Contract
A2: #2024#IC-Property | B2: 2024 | C2: IC-Property | D2: IC
A3: #2024#RC-Property | B3: 2024 | C3: RC-Property | D3: RC
A4: #2025#IC-Property | B4: 2025 | C4: IC-Property | D4: IC
A5: #2025#RC-Property | B5: 2025 | C5: RC-Property | D5: RC

Sheet Earned
A1: ICG | B1: Incurred | C1: Earned_Premium | D1: Earned_Commission
A2: #2024#IC-Property | B2: 46022 | C2: 2.7048939e+09 | D2: -8.4071295e+08
A3: #2024#IC-Property | B3: 46112 | C3: 2.6750056e+09 | D3: -8.3121337e+08
A4: #2024#IC-Property | B4: 46203 | C4: 2.6451173e+09 | D4: -8.2171379e+08
A5: #2024#IC-Property | B5: 46295 | C5: 2.615229e+09 | D5: -8.1221421e+08
A6: #2024#IC-Property | B6: 46387 | C6: 2.5853406e+09 | D6: -8.0271463e+08
A7: #2024#IC-Property | B7: 46477 | C7: 2.5554523e+09 | D7: -7.9321505e+08
A8: #2024#IC-Property | B8: 46568 | C8: 2.525564e+09 | D8: -7.8371547e+08
A9: #2024#IC-Property | B9: 46660 | C9: 2.4956756e+09 | D9: -7.7421588e+08
A10: #2024#IC-Property | B10: 46752 | C10: 2.4657873e+09 | D10: -7.647163e+08
A11: #2024#IC-Property | B11: 46843 | C11: 2.435899e+09 | D11: -7.5521672e+08
A12: #2024#IC-Property | B12: 46934 | C12: 2.4060106e+09 | D12: -7.4571714e+08
A13: #2024#IC-Property | B13: 47026 | C13: 2.3761223e+09 | D13: -7.3621756e+08
... A387: #2025#RC-Property | B387: 54788 | C387: 0 | D387: 0

Sheet Expected_CF
A1: ICG | B1: Incurred | C1: Expected_Premium | D1: Expected_Commission | E1: Expected_Acquisition
A2: #2025#IC-Property | B2: 45747 | C2: 2.5082465e+10 | D2: -3.7623697e+09 | E2: -1.2541232e+09
A3: #2025#IC-Property | B3: 45838 | C3: 3.5441376e+10 | D3: -4.9617927e+09 | E3: -1.5948619e+09
A4: #2025#IC-Property | B4: 45930 | C4: 5.1754642e+10 | D4: -7.5044231e+09 | E4: -2.0701857e+09
A5: #2025#RC-Property | B5: 45747 | C5: -1.1287109e+10 | D5: 3.6683104e+09 | E5: 0
A6: #2025#RC-Property | B6: 45838 | C6: -1.5948619e+10 | D6: 5.1833013e+09 | E6: 0
A7: #2025#RC-Property | B7: 45930 | C7: -2.3289589e+10 | D7: 7.5691164e+09 | E7: 0

Sheet Actual_CF
A1: ICG | B1: Incurred | C1: Actual_Premium | D1: Actual_Commission | E1: Actual_Acquisition
A2: #2025#IC-Property | B2: 45747 | C2: 2.5082465e+10 | D2: -3.7623697e+09 | E2: -1.2541232e+09
A3: #2025#IC-Property | B3: 45838 | C3: 3.5441376e+10 | D3: -4.9617927e+09 | E3: -1.5948619e+09
A4: #2025#IC-Property | B4: 45930 | C4: 5.1754642e+10 | D4: -7.5044231e+09 | E4: -2.0701857e+09
A5: #2025#RC-Property | B5: 45747 | C5: -1.1287109e+10 | D5: 3.6683104e+09 | E5: 0
A6: #2025#RC-Property | B6: 45838 | C6: -1.5948619e+10 | D6: 5.1833013e+09 | E6: 0
A7: #2025#RC-Property | B7: 45930 | C7: -2.3289589e+10 | D7: 7.5691164e+09 | E7: 0
A8: #2024#IC-Property | B8: 45747 | C8: 1.1505718e+09 | D8: -1.7258577e+08 | E8: 0
A9: #2024#IC-Property | B9: 45838 | C9: 3.2515024e+08 | D9: -45521034 | E9: 0
A10: #2024#IC-Property | B10: 45930 | C10: -9.4962647e+08 | D10: 1.3769584e+08 | E10: 0
A11: #2024#RC-Property | B11: 45747 | C11: -5.177573e+08 | D11: 1.6827112e+08 | E11: 0
A12: #2024#RC-Property | B12: 45838 | C12: -1.4631761e+08 | D12: 47553223 | E12: 0
A13: #2024#RC-Property | B13: 45930 | C13: 4.2733191e+08 | D13: -1.3888287e+08 | E13: 0

Sheet Locked_in_Rate
A1: ICG | B1: Locked_in_Rate
A2: #2024#IC-Property | B2: 0.0637305
A3: #2024#RC-Property | B3: 0.0637305
A4: #2025#IC-Property | B4: 0.059441333
A5: #2025#RC-Property | B5: 0.059441333

Sheet Current_Rate
A1: ICG | B1: Locked_in_Rate
A2: #2024#IC-Property | B2: 0.048974
A3: #2024#RC-Property | B3: 0.048974
A4: #2025#IC-Property | B4: 0.048974
A5: #2025#RC-Property | B5: 0.048974

Sheet Assumptions
A1: ICG | B1: Loss_Ratio | C1: Risk_Adjustment_Ratio | D1: PME_Ratio | E1: ULAE_Ratio | F1: Cancellation_Ratio | G1: Premium_Refund_Ratio | H1: NPR_Ratio
A2: #2024#IC-Property | B2: 0.4 | C2: 0.14 | D2: 0.045 | E2: 0.11 | F2: 0.07 | G2: 0.5 | H2: 0
A3: #2024#RC-Property | B3: 0.38 | C3: 0.13 | D3: 0 | E3: 0 | F3: 0.07 | G3: 0.5 | H3: 0.028
A4: #2025#IC-Property | B4: 0.4 | C4: 0.14 | D4: 0.045 | E4: 0.11 | F4: 0.07 | G4: 0.5 | H4: 0
A5: #2025#RC-Property | B5: 0.38 | C5: 0.13 | D5: 0 | E5: 0 | F5: 0.07 | G5: 0.5 | H5: 0.028

Sheet Cashflow Generator >>

Sheet CF_Gen_1
A1: ICG | B1: Cohort | C1: Portfolio | D1: Contract | E1: Valuation | F1: #Incurred | G1: Incurred | H1: Expected_Premium | I1: Expected_Commission | J1: Expected_Acquisition | K1: Earned_Premium | L1: Earned_Commission | M1: Loss_Ratio | N1: Risk_Adjustment_Ratio | O1: PME_Ratio | P1: ULAE_Ratio | Q1: Cancellation_Ratio | R1: Premium_Refund_Ratio | S1: NPR_Ratio | T1: Probability_of_Inforce | U1: Exp_Premium | V1: Exp_Commission | W1: Exp_Acquisition | X1: Exp_Expense | Y1: Exp_Claim | Z1: Exp_RA | AA1: Exp_NPR | AB1: Actual_Premium | AC1: Actual_Commission | AD1: Actual_Acquisition
A2: =ICG!$A$2 -> #2024#IC-Property | B2: =_xlfn.XLOOKUP(CF_Gen_1[[#This Row],[ICG]],ICG[ICG],ICG[Cohort]) -> 2024 | C2: =_xlfn.XLOOKUP(CF_Gen_1[[#This Row],[ICG]],ICG[ICG],ICG[Portfolio]) -> IC-Property | D2: =_xlfn.XLOOKUP(CF_Gen_1[[#This Row],[ICG]],ICG[ICG],ICG[Contract]) -> IC | E2: =ValuationDate -> 45930 | F2: 1 | G2: =EOMONTH(DATE(YEAR(CF_Gen_1[[#This Row],[Valuation]])-1,12,31),CF_Gen_1[[#This Row],['#Incurred]]*3) -> 45747 | H2: =SUMIFS(Expected_CF[Expected_Premium],Expected_CF[ICG],CF_Gen_1[[#This Row],[ICG]],Expected_CF[Incurred],CF_Gen_1[[#This Row],[Incurred]]) -> 0 | I2: =SUMIFS(Expected_CF[Expected_Commission],Expected_CF[ICG],CF_Gen_1[[#This Row],[ICG]],Expected_CF[Incurred],CF_Gen_1[[#This Row],[Incurred]]) -> 0 | J2: =IF(CF_Gen_1[[#This Row],[Contract]]="IC",SUMIFS(Expected_CF[Expected_Acquisition],Expected_CF[ICG],CF_Gen_1[[#This Row],[ICG]],Expected_CF[Incurred],CF_Gen_1[[#This Row],[Incurred]]),0) -> 0 | K2: =SUMIFS(Earned[Earned_Premium],Earned[ICG],CF_Gen_1[[#This Row],[ICG]],Earned[Incurred],CF_Gen_1[[#This Row],[Incurred]]) -> 0 | L2: =SUMIFS(Earned[Earned_Commission],Earned[ICG],CF_Gen_1[[#This Row],[ICG]],Earned[Incurred],CF_Gen_1[[#This Row],[Incurred]]) -> 0 | M2: =_xlfn.XLOOKUP(CF_Gen_1[[#This Row],[ICG]],Assumptions[ICG],Assumptions[Loss_Ratio]) -> 0.4 | N2: =_xlfn.XLOOKUP(CF_Gen_1[[#This Row],[ICG]],Assumptions[ICG],Assumptions[Risk_Adjustment_Ratio]) -> 0.14 | O2: =_xlfn.XLOOKUP(CF_Gen_1[[#This Row],[ICG]],Assumptions[ICG],Assumptions[PME_Ratio]) -> 0.045 | P2: =_xlfn.XLOOKUP(CF_Gen_1[[#This Row],[ICG]],Assumptions[ICG],Assumptions[ULAE_Ratio]) -> 0.11 | Q2: =_xlfn.XLOOKUP(CF_Gen_1[[#This Row],[ICG]],Assumptions[ICG],Assumptions[Cancellation_Ratio]) -> 0.07 | R2: =_xlfn.XLOOKUP(CF_Gen_1[[#This Row],[ICG]],Assumptions[ICG],Assumptions[Premium_Refund_Ratio]) -> 0.5 | S2: =IF(CF_Gen_1[[#This Row],[Contract]]="RC",_xlfn.XLOOKUP(CF_Gen_1[[#This Row],[ICG]],Assumptions[ICG],Assumptions[NPR_Ratio]),0) -> 0 | T2: 1 | U2: =IF(CF_Gen_1[[#This Row],[Incurred]]<=CF_Gen_1[[#This Row],[Valuation]],CF_Gen_1[[#This Row],[Expected_Premium]],-CF_Gen_1[[#This Row],[Probability_of_Inforce]]*CF_Gen_1[[#This Row],[Premium_Refund_Ratio]]*CF_Gen_1[[#This Row],[Cancellation_Ratio]]*SUM(K2:K$105)) -> 0 | V2: =IF(CF_Gen_1[[#This Row],[Incurred]]<=CF_Gen_1[[#This Row],[Valuation]],CF_Gen_1[[#This Row],[Expected_Commission]],-CF_Gen_1[[#This Row],[Probability_of_Inforce]]*CF_Gen_1[[#This Row],[Premium_Refund_Ratio]]*CF_Gen_1[[#This Row],[Cancellation_Ratio]]*SUM(L2:L$105)) -> 0 | W2: =CF_Gen_1[[#This Row],[Expected_Acquisition]] -> 0 | X2: =-CF_Gen_1[[#This Row],[Probability_of_Inforce]]*CF_Gen_1[[#This Row],[Earned_Premium]]*(1-CF_Gen_1[[#This Row],[Cancellation_Ratio]])*CF_Gen_1[[#This Row],[PME_Ratio]]+CF_Gen_1[[#This Row],[ULAE_Ratio]]*CF_Gen_1[[#This Row],[Exp_Claim]] -> 0 | Y2: =-CF_Gen_1[[#This Row],[Probability_of_Inforce]]*CF_Gen_1[[#This Row],[Earned_Premium]]*(1-CF_Gen_1[[#This Row],[Cancellation_Ratio]])*CF_Gen_1[[#This Row],[Loss_Ratio]] -> 0 | Z2: =CF_Gen_1[[#This Row],[Exp_Claim]]*CF_Gen_1[[#This Row],[Risk_Adjustment_Ratio]] -> 0 | AA2: =IF(CF_Gen_1[[#This Row],[Contract]]="RC",-CF_Gen_1[[#This Row],[NPR_Ratio]]*CF_Gen_1[[#This Row],[Exp_Claim]],0) -> 0 | AB2: =SUMIFS(Actual_CF[Actual_Premium],Actual_CF[ICG],CF_Gen_1[[#This Row],[ICG]],Actual_CF[Incurred],CF_Gen_1[[#This Row],[Incurred]]) -> 1.1505718e+09 | AC2: =SUMIFS(Actual_CF[Actual_Commission],Actual_CF[ICG],CF_Gen_1[[#This Row],[ICG]],Actual_CF[Incurred],CF_Gen_1[[#This Row],[Incurred]]) -> -1.7258577e+08 | AD2: =SUMIFS(Actual_CF[Actual_Acquisition],Actual_CF[ICG],CF_Gen_1[[#This Row],[ICG]],Actual_CF[Incurred],CF_Gen_1[[#This Row],[Incurred]]) -> 0
A3: =A2 -> #2024#IC-Property | B3: =_xlfn.XLOOKUP(CF_Gen_1[[#This Row],[ICG]],ICG[ICG],ICG[Cohort]) -> 2024 | C3: =_xlfn.XLOOKUP(CF_Gen_1[[#This Row],[ICG]],ICG[ICG],ICG[Portfolio]) -> IC-Property | D3: =_xlfn.XLOOKUP(CF_Gen_1[[#This Row],[ICG]],ICG[ICG],ICG[Contract]) -> IC | E3: =ValuationDate -> 45930 | F3: 2 | G3: =EOMONTH(DATE(YEAR(CF_Gen_1[[#This Row],[Valuation]])-1,12,31),CF_Gen_1[[#This Row],['#Incurred]]*3) -> 45838 | H3: =SUMIFS(Expected_CF[Expected_Premium],Expected_CF[ICG],CF_Gen_1[[#This Row],[ICG]],Expected_CF[Incurred],CF_Gen_1[[#This Row],[Incurred]]) -> 0 | I3: =SUMIFS(Expected_CF[Expected_Commission],Expected_CF[ICG],CF_Gen_1[[#This Row],[ICG]],Expected_CF[Incurred],CF_Gen_1[[#This Row],[Incurred]]) -> 0 | J3: =IF(CF_Gen_1[[#This Row],[Contract]]="IC",SUMIFS(Expected_CF[Expected_Acquisition],Expected_CF[ICG],CF_Gen_1[[#This Row],[ICG]],Expected_CF[Incurred],CF_Gen_1[[#This Row],[Incurred]]),0) -> 0 | K3: =SUMIFS(Earned[Earned_Premium],Earned[ICG],CF_Gen_1[[#This Row],[ICG]],Earned[Incurred],CF_Gen_1[[#This Row],[Incurred]]) -> 0 | L3: =SUMIFS(Earned[Earned_Commission],Earned[ICG],CF_Gen_1[[#This Row],[ICG]],Earned[Incurred],CF_Gen_1[[#This Row],[Incurred]]) -> 0 | M3: =_xlfn.XLOOKUP(CF_Gen_1[[#This Row],[ICG]],Assumptions[ICG],Assumptions[Loss_Ratio]) -> 0.4 | N3: =_xlfn.XLOOKUP(CF_Gen_1[[#This Row],[ICG]],Assumptions[ICG],Assumptions[Risk_Adjustment_Ratio]) -> 0.14 | O3: =_xlfn.XLOOKUP(CF_Gen_1[[#This Row],[ICG]],Assumptions[ICG],Assumptions[PME_Ratio]) -> 0.045 | P3: =_xlfn.XLOOKUP(CF_Gen_1[[#This Row],[ICG]],Assumptions[ICG],Assumptions[ULAE_Ratio]) -> 0.11 | Q3: =_xlfn.XLOOKUP(CF_Gen_1[[#This Row],[ICG]],Assumptions[ICG],Assumptions[Cancellation_Ratio]) -> 0.07 | R3: =_xlfn.XLOOKUP(CF_Gen_1[[#This Row],[ICG]],Assumptions[ICG],Assumptions[Premium_Refund_Ratio]) -> 0.5 | S3: =IF(CF_Gen_1[[#This Row],[Contract]]="RC",_xlfn.XLOOKUP(CF_Gen_1[[#This Row],[ICG]],Assumptions[ICG],Assumptions[NPR_Ratio]),0) -> 0 | T3: =T2*(1-CF_Gen_1[[#This Row],[Cancellation_Ratio]]) -> 0.93 | U3: =IF(CF_Gen_1[[#This Row],[Incurred]]<=CF_Gen_1[[#This Row],[Valuation]],CF_Gen_1[[#This Row],[Expected_Premium]],-CF_Gen_1[[#This Row],[Probability_of_Inforce]]*CF_Gen_1[[#This Row],[Premium_Refund_Ratio]]*CF_Gen_1[[#This Row],[Cancellation_Ratio]]*SUM(K3:K$105)) -> 0 | V3: =IF(CF_Gen_1[[#This Row],[Incurred]]<=CF_Gen_1[[#This Row],[Valuation]],CF_Gen_1[[#This Row],[Expected_Commission]],-CF_Gen_1[[#This Row],[Probability_of_Inforce]]*CF_Gen_1[[#This Row],[Premium_Refund_Ratio]]*CF_Gen_1[[#This Row],[Cancellation_Ratio]]*SUM(L3:L$105)) -> 0 | W3: =CF_Gen_1[[#This Row],[Expected_Acquisition]] -> 0 | X3: =-CF_Gen_1[[#This Row],[Probability_of_Inforce]]*CF_Gen_1[[#This Row],[Earned_Premium]]*(1-CF_Gen_1[[#This Row],[Cancellation_Ratio]])*CF_Gen_1[[#This Row],[PME_Ratio]]+CF_Gen_1[[#This Row],[ULAE_Ratio]]*CF_Gen_1[[#This Row],[Exp_Claim]] -> 0 | Y3: =-CF_Gen_1[[#This Row],[Probability_of_Inforce]]*CF_Gen_1[[#This Row],[Earned_Premium]]*(1-CF_Gen_1[[#This Row],[Cancellation_Ratio]])*CF_Gen_1[[#This Row],[Loss_Ratio]] -> 0 | Z3: =CF_Gen_1[[#This Row],[Exp_Claim]]*CF_Gen_1[[#This Row],[Risk_Adjustment_Ratio]] -> 0 | AA3: =IF(CF_Gen_1[[#This Row],[Contract]]="RC",-CF_Gen_1[[#This Row],[NPR_Ratio]]*CF_Gen_1[[#This Row],[Exp_Claim]],0) -> 0 | AB3: =SUMIFS(Actual_CF[Actual_Premium],Actual_CF[ICG],CF_Gen_1[[#This Row],[ICG]],Actual_CF[Incurred],CF_Gen_1[[#This Row],[Incurred]]) -> 3.2515024e+08 | AC3: =SUMIFS(Actual_CF[Actual_Commission],Actual_CF[ICG],CF_Gen_1[[#This Row],[ICG]],Actual_CF[Incurred],CF_Gen_1[[#This Row],[Incurred]]) -> -45521034 | AD3: =SUMIFS(Actual_CF[Actual_Acquisition],Actual_CF[ICG],CF_Gen_1[[#This Row],[ICG]],Actual_CF[Incurred],CF_Gen_1[[#This Row],[Incurred]]) -> 0
A4: =A3 -> #2024#IC-Property | B4: =_xlfn.XLOOKUP(CF_Gen_1[[#This Row],[ICG]],ICG[ICG],ICG[Cohort]) -> 2024 | C4: =_xlfn.XLOOKUP(CF_Gen_1[[#This Row],[ICG]],ICG[ICG],ICG[Portfolio]) -> IC-Property | D4: =_xlfn.XLOOKUP(CF_Gen_1[[#This Row],[ICG]],ICG[ICG],ICG[Contract]) -> IC | E4: =ValuationDate -> 45930 | F4: 3 | G4: =EOMONTH(DATE(YEAR(CF_Gen_1[[#This Row],[Valuation]])-1,12,31),CF_Gen_1[[#This Row],['#Incurred]]*3) -> 45930 | H4: =SUMIFS(Expected_CF[Expected_Premium],Expected_CF[ICG],CF_Gen_1[[#This Row],[ICG]],Expected_CF[Incurred],CF_Gen_1[[#This Row],[Incurred]]) -> 0 | I4: =SUMIFS(Expected_CF[Expected_Commission],Expected_CF[ICG],CF_Gen_1[[#This Row],[ICG]],Expected_CF[Incurred],CF_Gen_1[[#This Row],[Incurred]]) -> 0 | J4: =IF(CF_Gen_1[[#This Row],[Contract]]="IC",SUMIFS(Expected_CF[Expected_Acquisition],Expected_CF[ICG],CF_Gen_1[[#This Row],[ICG]],Expected_CF[Incurred],CF_Gen_1[[#This Row],[Incurred]]),0) -> 0 | K4: =SUMIFS(Earned[Earned_Premium],Earned[ICG],CF_Gen_1[[#This Row],[ICG]],Earned[Incurred],CF_Gen_1[[#This Row],[Incurred]]) -> 0 | L4: =SUMIFS(Earned[Earned_Commission],Earned[ICG],CF_Gen_1[[#This Row],[ICG]],Earned[Incurred],CF_Gen_1[[#This Row],[Incurred]]) -> 0 | M4: =_xlfn.XLOOKUP(CF_Gen_1[[#This Row],[ICG]],Assumptions[ICG],Assumptions[Loss_Ratio]) -> 0.4 | N4: =_xlfn.XLOOKUP(CF_Gen_1[[#This Row],[ICG]],Assumptions[ICG],Assumptions[Risk_Adjustment_Ratio]) -> 0.14 | O4: =_xlfn.XLOOKUP(CF_Gen_1[[#This Row],[ICG]],Assumptions[ICG],Assumptions[PME_Ratio]) -> 0.045 | P4: =_xlfn.XLOOKUP(CF_Gen_1[[#This Row],[ICG]],Assumptions[ICG],Assumptions[ULAE_Ratio]) -> 0.11 | Q4: =_xlfn.XLOOKUP(CF_Gen_1[[#This Row],[ICG]],Assumptions[ICG],Assumptions[Cancellation_Ratio]) -> 0.07 | R4: =_xlfn.XLOOKUP(CF_Gen_1[[#This Row],[ICG]],Assumptions[ICG],Assumptions[Premium_Refund_Ratio]) -> 0.5 | S4: =IF(CF_Gen_1[[#This Row],[Contract]]="RC",_xlfn.XLOOKUP(CF_Gen_1[[#This Row],[ICG]],Assumptions[ICG],Assumptions[NPR_Ratio]),0) -> 0 | T4: =T3*(1-CF_Gen_1[[#This Row],[Cancellation_Ratio]]) -> 0.8649 | U4: =IF(CF_Gen_1[[#This Row],[Incurred]]<=CF_Gen_1[[#This Row],[Valuation]],CF_Gen_1[[#This Row],[Expected_Premium]],-CF_Gen_1[[#This Row],[Probability_of_Inforce]]*CF_Gen_1[[#This Row],[Premium_Refund_Ratio]]*CF_Gen_1[[#This Row],[Cancellation_Ratio]]*SUM(K4:K$105)) -> 0 | V4: =IF(CF_Gen_1[[#This Row],[Incurred]]<=CF_Gen_1[[#This Row],[Valuation]],CF_Gen_1[[#This Row],[Expected_Commission]],-CF_Gen_1[[#This Row],[Probability_of_Inforce]]*CF_Gen_1[[#This Row],[Premium_Refund_Ratio]]*CF_Gen_1[[#This Row],[Cancellation_Ratio]]*SUM(L4:L$105)) -> 0 | W4: =CF_Gen_1[[#This Row],[Expected_Acquisition]] -> 0 | X4: =-CF_Gen_1[[#This Row],[Probability_of_Inforce]]*CF_Gen_1[[#This Row],[Earned_Premium]]*(1-CF_Gen_1[[#This Row],[Cancellation_Ratio]])*CF_Gen_1[[#This Row],[PME_Ratio]]+CF_Gen_1[[#This Row],[ULAE_Ratio]]*CF_Gen_1[[#This Row],[Exp_Claim]] -> 0 | Y4: =-CF_Gen_1[[#This Row],[Probability_of_Inforce]]*CF_Gen_1[[#This Row],[Earned_Premium]]*(1-CF_Gen_1[[#This Row],[Cancellation_Ratio]])*CF_Gen_1[[#This Row],[Loss_Ratio]] -> 0 | Z4: =CF_Gen_1[[#This Row],[Exp_Claim]]*CF_Gen_1[[#This Row],[Risk_Adjustment_Ratio]] -> 0 | AA4: =IF(CF_Gen_1[[#This Row],[Contract]]="RC",-CF_Gen_1[[#This Row],[NPR_Ratio]]*CF_Gen_1[[#This Row],[Exp_Claim]],0) -> 0 | AB4: =SUMIFS(Actual_CF[Actual_Premium],Actual_CF[ICG],CF_Gen_1[[#This Row],[ICG]],Actual_CF[Incurred],CF_Gen_1[[#This Row],[Incurred]]) -> -9.4962647e+08 | AC4: =SUMIFS(Actual_CF[Actual_Commission],Actual_CF[ICG],CF_Gen_1[[#This Row],[ICG]],Actual_CF[Incurred],CF_Gen_1[[#This Row],[Incurred]]) -> 1.3769584e+08 | AD4: =SUMIFS(Actual_CF[Actual_Acquisition],Actual_CF[ICG],CF_Gen_1[[#This Row],[ICG]],Actual_CF[Incurred],CF_Gen_1[[#This Row],[Incurred]]) -> 0
A5: =A4 -> #2024#IC-Property | B5: =_xlfn.XLOOKUP(CF_Gen_1[[#This Row],[ICG]],ICG[ICG],ICG[Cohort]) -> 2024 | C5: =_xlfn.XLOOKUP(CF_Gen_1[[#This Row],[ICG]],ICG[ICG],ICG[Portfolio]) -> IC-Property | D5: =_xlfn.XLOOKUP(CF_Gen_1[[#This Row],[ICG]],ICG[ICG],ICG[Contract]) -> IC | E5: =ValuationDate -> 45930 | F5: 4 | G5: =EOMONTH(DATE(YEAR(CF_Gen_1[[#This Row],[Valuation]])-1,12,31),CF_Gen_1[[#This Row],['#Incurred]]*3) -> 46022 | H5: =SUMIFS(Expected_CF[Expected_Premium],Expected_CF[ICG],CF_Gen_1[[#This Row],[ICG]],Expected_CF[Incurred],CF_Gen_1[[#This Row],[Incurred]]) -> 0 | I5: =SUMIFS(Expected_CF[Expected_Commission],Expected_CF[ICG],CF_Gen_1[[#This Row],[ICG]],Expected_CF[Incurred],CF_Gen_1[[#This Row],[Incurred]]) -> 0 | J5: =IF(CF_Gen_1[[#This Row],[Contract]]="IC",SUMIFS(Expected_CF[Expected_Acquisition],Expected_CF[ICG],CF_Gen_1[[#This Row],[ICG]],Expected_CF[Incurred],CF_Gen_1[[#This Row],[Incurred]]),0) -> 0 | K5: =SUMIFS(Earned[Earned_Premium],Earned[ICG],CF_Gen_1[[#This Row],[ICG]],Earned[Incurred],CF_Gen_1[[#This Row],[Incurred]]) -> 2.7048939e+09 | L5: =SUMIFS(Earned[Earned_Commission],Earned[ICG],CF_Gen_1[[#This Row],[ICG]],Earned[Incurred],CF_Gen_1[[#This Row],[Incurred]]) -> -8.4071295e+08 | M5: =_xlfn.XLOOKUP(CF_Gen_1[[#This Row],[ICG]],Assumptions[ICG],Assumptions[Loss_Ratio]) -> 0.4 | N5: =_xlfn.XLOOKUP(CF_Gen_1[[#This Row],[ICG]],Assumptions[ICG],Assumptions[Risk_Adjustment_Ratio]) -> 0.14 | O5: =_xlfn.XLOOKUP(CF_Gen_1[[#This Row],[ICG]],Assumptions[ICG],Assumptions[PME_Ratio]) -> 0.045 | P5: =_xlfn.XLOOKUP(CF_Gen_1[[#This Row],[ICG]],Assumptions[ICG],Assumptions[ULAE_Ratio]) -> 0.11 | Q5: =_xlfn.XLOOKUP(CF_Gen_1[[#This Row],[ICG]],Assumptions[ICG],Assumptions[Cancellation_Ratio]) -> 0.07 | R5: =_xlfn.XLOOKUP(CF_Gen_1[[#This Row],[ICG]],Assumptions[ICG],Assumptions[Premium_Refund_Ratio]) -> 0.5 | S5: =IF(CF_Gen_1[[#This Row],[Contract]]="RC",_xlfn.XLOOKUP(CF_Gen_1[[#This Row],[ICG]],Assumptions[ICG],Assumptions[NPR_Ratio]),0) -> 0 | T5: =T4*(1-CF_Gen_1[[#This Row],[Cancellation_Ratio]]) -> 0.804357 | U5: =IF(CF_Gen_1[[#This Row],[Incurred]]<=CF_Gen_1[[#This Row],[Valuation]],CF_Gen_1[[#This Row],[Expected_Premium]],-CF_Gen_1[[#This Row],[Probability_of_Inforce]]*CF_Gen_1[[#This Row],[Premium_Refund_Ratio]]*CF_Gen_1[[#This Row],[Cancellation_Ratio]]*SUM(K5:K$105)) -> -3.4843661e+09 | V5: =IF(CF_Gen_1[[#This Row],[Incurred]]<=CF_Gen_1[[#This Row],[Valuation]],CF_Gen_1[[#This Row],[Expected_Commission]],-CF_Gen_1[[#This Row],[Probability_of_Inforce]]*CF_Gen_1[[#This Row],[Premium_Refund_Ratio]]*CF_Gen_1[[#This Row],[Cancellation_Ratio]]*SUM(L5:L$105)) -> 1.0598525e+09 | W5: =CF_Gen_1[[#This Row],[Expected_Acquisition]] -> 0 | X5: =-CF_Gen_1[[#This Row],[Probability_of_Inforce]]*CF_Gen_1[[#This Row],[Earned_Premium]]*(1-CF_Gen_1[[#This Row],[Cancellation_Ratio]])*CF_Gen_1[[#This Row],[PME_Ratio]]+CF_Gen_1[[#This Row],[ULAE_Ratio]]*CF_Gen_1[[#This Row],[Exp_Claim]] -> -1.8008272e+08 | Y5: =-CF_Gen_1[[#This Row],[Probability_of_Inforce]]*CF_Gen_1[[#This Row],[Earned_Premium]]*(1-CF_Gen_1[[#This Row],[Cancellation_Ratio]])*CF_Gen_1[[#This Row],[Loss_Ratio]] -> -8.0936054e+08 | Z5: =CF_Gen_1[[#This Row],[Exp_Claim]]*CF_Gen_1[[#This Row],[Risk_Adjustment_Ratio]] -> -1.1331048e+08 | AA5: =IF(CF_Gen_1[[#This Row],[Contract]]="RC",-CF_Gen_1[[#This Row],[NPR_Ratio]]*CF_Gen_1[[#This Row],[Exp_Claim]],0) -> 0 | AB5: =SUMIFS(Actual_CF[Actual_Premium],Actual_CF[ICG],CF_Gen_1[[#This Row],[ICG]],Actual_CF[Incurred],CF_Gen_1[[#This Row],[Incurred]]) -> 0 | AC5: =SUMIFS(Actual_CF[Actual_Commission],Actual_CF[ICG],CF_Gen_1[[#This Row],[ICG]],Actual_CF[Incurred],CF_Gen_1[[#This Row],[Incurred]]) -> 0 | AD5: =SUMIFS(Actual_CF[Actual_Acquisition],Actual_CF[ICG],CF_Gen_1[[#This Row],[ICG]],Actual_CF[Incurred],CF_Gen_1[[#This Row],[Incurred]]) -> 0
A6: =A5 -> #2024#IC-Property | B6: =_xlfn.XLOOKUP(CF_Gen_1[[#This Row],[ICG]],ICG[ICG],ICG[Cohort]) -> 2024 | C6: =_xlfn.XLOOKUP(CF_Gen_1[[#This Row],[ICG]],ICG[ICG],ICG[Portfolio]) -> IC-Property | D6: =_xlfn.XLOOKUP(CF_Gen_1[[#This Row],[ICG]],ICG[ICG],ICG[Contract]) -> IC | E6: =ValuationDate -> 45930 | F6: 5 | G6: =EOMONTH(DATE(YEAR(CF_Gen_1[[#This Row],[Valuation]])-1,12,31),CF_Gen_1[[#This Row],['#Incurred]]*3) -> 46112 | H6: =SUMIFS(Expected_CF[Expected_Premium],Expected_CF[ICG],CF_Gen_1[[#This Row],[ICG]],Expected_CF[Incurred],CF_Gen_1[[#This Row],[Incurred]]) -> 0 | I6: =SUMIFS(Expected_CF[Expected_Commission],Expected_CF[ICG],CF_Gen_1[[#This Row],[ICG]],Expected_CF[Incurred],CF_Gen_1[[#This Row],[Incurred]]) -> 0 | J6: =IF(CF_Gen_1[[#This Row],[Contract]]="IC",SUMIFS(Expected_CF[Expected_Acquisition],Expected_CF[ICG],CF_Gen_1[[#This Row],[ICG]],Expected_CF[Incurred],CF_Gen_1[[#This Row],[Incurred]]),0) -> 0 | K6: =SUMIFS(Earned[Earned_Premium],Earned[ICG],CF_Gen_1[[#This Row],[ICG]],Earned[Incurred],CF_Gen_1[[#This Row],[Incurred]]) -> 2.6750056e+09 | L6: =SUMIFS(Earned[Earned_Commission],Earned[ICG],CF_Gen_1[[#This Row],[ICG]],Earned[Incurred],CF_Gen_1[[#This Row],[Incurred]]) -> -8.3121337e+08 | M6: =_xlfn.XLOOKUP(CF_Gen_1[[#This Row],[ICG]],Assumptions[ICG],Assumptions[Loss_Ratio]) -> 0.4 | N6: =_xlfn.XLOOKUP(CF_Gen_1[[#This Row],[ICG]],Assumptions[ICG],Assumptions[Risk_Adjustment_Ratio]) -> 0.14 | O6: =_xlfn.XLOOKUP(CF_Gen_1[[#This Row],[ICG]],Assumptions[ICG],Assumptions[PME_Ratio]) -> 0.045 | P6: =_xlfn.XLOOKUP(CF_Gen_1[[#This Row],[ICG]],Assumptions[ICG],Assumptions[ULAE_Ratio]) -> 0.11 | Q6: =_xlfn.XLOOKUP(CF_Gen_1[[#This Row],[ICG]],Assumptions[ICG],Assumptions[Cancellation_Ratio]) -> 0.07 | R6: =_xlfn.XLOOKUP(CF_Gen_1[[#This Row],[ICG]],Assumptions[ICG],Assumptions[Premium_Refund_Ratio]) -> 0.5 | S6: =IF(CF_Gen_1[[#This Row],[Contract]]="RC",_xlfn.XLOOKUP(CF_Gen_1[[#This Row],[ICG]],Assumptions[ICG],Assumptions[NPR_Ratio]),0) -> 0 | T6: =T5*(1-CF_Gen_1[[#This Row],[Cancellation_Ratio]]) -> 0.74805201 | U6: =IF(CF_Gen_1[[#This Row],[Incurred]]<=CF_Gen_1[[#This Row],[Valuation]],CF_Gen_1[[#This Row],[Expected_Premium]],-CF_Gen_1[[#This Row],[Probability_of_Inforce]]*CF_Gen_1[[#This Row],[Premium_Refund_Ratio]]*CF_Gen_1[[#This Row],[Cancellation_Ratio]]*SUM(K6:K$105)) -> -3.1696415e+09 | V6: =IF(CF_Gen_1[[#This Row],[Incurred]]<=CF_Gen_1[[#This Row],[Valuation]],CF_Gen_1[[#This Row],[Expected_Commission]],-CF_Gen_1[[#This Row],[Probability_of_Inforce]]*CF_Gen_1[[#This Row],[Premium_Refund_Ratio]]*CF_Gen_1[[#This Row],[Cancellation_Ratio]]*SUM(L6:L$105)) -> 9.6365144e+08 | W6: =CF_Gen_1[[#This Row],[Expected_Acquisition]] -> 0 | X6: =-CF_Gen_1[[#This Row],[Probability_of_Inforce]]*CF_Gen_1[[#This Row],[Earned_Premium]]*(1-CF_Gen_1[[#This Row],[Cancellation_Ratio]])*CF_Gen_1[[#This Row],[PME_Ratio]]+CF_Gen_1[[#This Row],[ULAE_Ratio]]*CF_Gen_1[[#This Row],[Exp_Claim]] -> -1.6562636e+08 | Y6: =-CF_Gen_1[[#This Row],[Probability_of_Inforce]]*CF_Gen_1[[#This Row],[Earned_Premium]]*(1-CF_Gen_1[[#This Row],[Cancellation_Ratio]])*CF_Gen_1[[#This Row],[Loss_Ratio]] -> -7.4438812e+08 | Z6: =CF_Gen_1[[#This Row],[Exp_Claim]]*CF_Gen_1[[#This Row],[Risk_Adjustment_Ratio]] -> -1.0421434e+08 | AA6: =IF(CF_Gen_1[[#This Row],[Contract]]="RC",-CF_Gen_1[[#This Row],[NPR_Ratio]]*CF_Gen_1[[#This Row],[Exp_Claim]],0) -> 0 | AB6: =SUMIFS(Actual_CF[Actual_Premium],Actual_CF[ICG],CF_Gen_1[[#This Row],[ICG]],Actual_CF[Incurred],CF_Gen_1[[#This Row],[Incurred]]) -> 0 | AC6: =SUMIFS(Actual_CF[Actual_Commission],Actual_CF[ICG],CF_Gen_1[[#This Row],[ICG]],Actual_CF[Incurred],CF_Gen_1[[#This Row],[Incurred]]) -> 0 | AD6: =SUMIFS(Actual_CF[Actual_Acquisition],Actual_CF[ICG],CF_Gen_1[[#This Row],[ICG]],Actual_CF[Incurred],CF_Gen_1[[#This Row],[Incurred]]) -> 0
A7: =A6 -> #2024#IC-Property | B7: =_xlfn.XLOOKUP(CF_Gen_1[[#This Row],[ICG]],ICG[ICG],ICG[Cohort]) -> 2024 | C7: =_xlfn.XLOOKUP(CF_Gen_1[[#This Row],[ICG]],ICG[ICG],ICG[Portfolio]) -> IC-Property | D7: =_xlfn.XLOOKUP(CF_Gen_1[[#This Row],[ICG]],ICG[ICG],ICG[Contract]) -> IC | E7: =ValuationDate -> 45930 | F7: 6 | G7: =EOMONTH(DATE(YEAR(CF_Gen_1[[#This Row],[Valuation]])-1,12,31),CF_Gen_1[[#This Row],['#Incurred]]*3) -> 46203 | H7: =SUMIFS(Expected_CF[Expected_Premium],Expected_CF[ICG],CF_Gen_1[[#This Row],[ICG]],Expected_CF[Incurred],CF_Gen_1[[#This Row],[Incurred]]) -> 0 | I7: =SUMIFS(Expected_CF[Expected_Commission],Expected_CF[ICG],CF_Gen_1[[#This Row],[ICG]],Expected_CF[Incurred],CF_Gen_1[[#This Row],[Incurred]]) -> 0 | J7: =IF(CF_Gen_1[[#This Row],[Contract]]="IC",SUMIFS(Expected_CF[Expected_Acquisition],Expected_CF[ICG],CF_Gen_1[[#This Row],[ICG]],Expected_CF[Incurred],CF_Gen_1[[#This Row],[Incurred]]),0) -> 0 | K7: =SUMIFS(Earned[Earned_Premium],Earned[ICG],CF_Gen_1[[#This Row],[ICG]],Earned[Incurred],CF_Gen_1[[#This Row],[Incurred]]) -> 2.6451173e+09 | L7: =SUMIFS(Earned[Earned_Commission],Earned[ICG],CF_Gen_1[[#This Row],[ICG]],Earned[Incurred],CF_Gen_1[[#This Row],[Incurred]]) -> -8.2171379e+08 | M7: =_xlfn.XLOOKUP(CF_Gen_1[[#This Row],[ICG]],Assumptions[ICG],Assumptions[Loss_Ratio]) -> 0.4 | N7: =_xlfn.XLOOKUP(CF_Gen_1[[#This Row],[ICG]],Assumptions[ICG],Assumptions[Risk_Adjustment_Ratio]) -> 0.14 | O7: =_xlfn.XLOOKUP(CF_Gen_1[[#This Row],[ICG]],Assumptions[ICG],Assumptions[PME_Ratio]) -> 0.045 | P7: =_xlfn.XLOOKUP(CF_Gen_1[[#This Row],[ICG]],Assumptions[ICG],Assumptions[ULAE_Ratio]) -> 0.11 | Q7: =_xlfn.XLOOKUP(CF_Gen_1[[#This Row],[ICG]],Assumptions[ICG],Assumptions[Cancellation_Ratio]) -> 0.07 | R7: =_xlfn.XLOOKUP(CF_Gen_1[[#This Row],[ICG]],Assumptions[ICG],Assumptions[Premium_Refund_Ratio]) -> 0.5 | S7: =IF(CF_Gen_1[[#This Row],[Contract]]="RC",_xlfn.XLOOKUP(CF_Gen_1[[#This Row],[ICG]],Assumptions[ICG],Assumptions[NPR_Ratio]),0) -> 0 | T7: =T6*(1-CF_Gen_1[[#This Row],[Cancellation_Ratio]]) -> 0.69568837 | U7: =IF(CF_Gen_1[[#This Row],[Incurred]]<=CF_Gen_1[[#This Row],[Valuation]],CF_Gen_1[[#This Row],[Expected_Premium]],-CF_Gen_1[[#This Row],[Probability_of_Inforce]]*CF_Gen_1[[#This Row],[Premium_Refund_Ratio]]*CF_Gen_1[[#This Row],[Cancellation_Ratio]]*SUM(K7:K$105)) -> -2.8826326e+09 | V7: =IF(CF_Gen_1[[#This Row],[Incurred]]<=CF_Gen_1[[#This Row],[Valuation]],CF_Gen_1[[#This Row],[Expected_Commission]],-CF_Gen_1[[#This Row],[Probability_of_Inforce]]*CF_Gen_1[[#This Row],[Premium_Refund_Ratio]]*CF_Gen_1[[#This Row],[Cancellation_Ratio]]*SUM(L7:L$105)) -> 8.7595654e+08 | W7: =CF_Gen_1[[#This Row],[Expected_Acquisition]] -> 0 | X7: =-CF_Gen_1[[#This Row],[Probability_of_Inforce]]*CF_Gen_1[[#This Row],[Earned_Premium]]*(1-CF_Gen_1[[#This Row],[Cancellation_Ratio]])*CF_Gen_1[[#This Row],[PME_Ratio]]+CF_Gen_1[[#This Row],[ULAE_Ratio]]*CF_Gen_1[[#This Row],[Exp_Claim]] -> -1.5231148e+08 | Y7: =-CF_Gen_1[[#This Row],[Probability_of_Inforce]]*CF_Gen_1[[#This Row],[Earned_Premium]]*(1-CF_Gen_1[[#This Row],[Cancellation_Ratio]])*CF_Gen_1[[#This Row],[Loss_Ratio]] -> -6.8454597e+08 | Z7: =CF_Gen_1[[#This Row],[Exp_Claim]]*CF_Gen_1[[#This Row],[Risk_Adjustment_Ratio]] -> -95836435 | AA7: =IF(CF_Gen_1[[#This Row],[Contract]]="RC",-CF_Gen_1[[#This Row],[NPR_Ratio]]*CF_Gen_1[[#This Row],[Exp_Claim]],0) -> 0 | AB7: =SUMIFS(Actual_CF[Actual_Premium],Actual_CF[ICG],CF_Gen_1[[#This Row],[ICG]],Actual_CF[Incurred],CF_Gen_1[[#This Row],[Incurred]]) -> 0 | AC7: =SUMIFS(Actual_CF[Actual_Commission],Actual_CF[ICG],CF_Gen_1[[#This Row],[ICG]],Actual_CF[Incurred],CF_Gen_1[[#This Row],[Incurred]]) -> 0 | AD7: =SUMIFS(Actual_CF[Actual_Acquisition],Actual_CF[ICG],CF_Gen_1[[#This Row],[ICG]],Actual_CF[Incurred],CF_Gen_1[[#This Row],[Incurred]]) -> 0
A8: =A7 -> #2024#IC-Property | B8: =_xlfn.XLOOKUP(CF_Gen_1[[#This Row],[ICG]],ICG[ICG],ICG[Cohort]) -> 2024 | C8: =_xlfn.XLOOKUP(CF_Gen_1[[#This Row],[ICG]],ICG[ICG],ICG[Portfolio]) -> IC-Property | D8: =_xlfn.XLOOKUP(CF_Gen_1[[#This Row],[ICG]],ICG[ICG],ICG[Contract]) -> IC | E8: =ValuationDate -> 45930 | F8: 7 | G8: =EOMONTH(DATE(YEAR(CF_Gen_1[[#This Row],[Valuation]])-1,12,31),CF_Gen_1[[#This Row],['#Incurred]]*3) -> 46295 | H8: =SUMIFS(Expected_CF[Expected_Premium],Expected_CF[ICG],CF_Gen_1[[#This Row],[ICG]],Expected_CF[Incurred],CF_Gen_1[[#This Row],[Incurred]]) -> 0 | I8: =SUMIFS(Expected_CF[Expected_Commission],Expected_CF[ICG],CF_Gen_1[[#This Row],[ICG]],Expected_CF[Incurred],CF_Gen_1[[#This Row],[Incurred]]) -> 0 | J8: =IF(CF_Gen_1[[#This Row],[Contract]]="IC",SUMIFS(Expected_CF[Expected_Acquisition],Expected_CF[ICG],CF_Gen_1[[#This Row],[ICG]],Expected_CF[Incurred],CF_Gen_1[[#This Row],[Incurred]]),0) -> 0 | K8: =SUMIFS(Earned[Earned_Premium],Earned[ICG],CF_Gen_1[[#This Row],[ICG]],Earned[Incurred],CF_Gen_1[[#This Row],[Incurred]]) -> 2.615229e+09 | L8: =SUMIFS(Earned[Earned_Commission],Earned[ICG],CF_Gen_1[[#This Row],[ICG]],Earned[Incurred],CF_Gen_1[[#This Row],[Incurred]]) -> -8.1221421e+08 | M8: =_xlfn.XLOOKUP(CF_Gen_1[[#This Row],[ICG]],Assumptions[ICG],Assumptions[Loss_Ratio]) -> 0.4 | N8: =_xlfn.XLOOKUP(CF_Gen_1[[#This Row],[ICG]],Assumptions[ICG],Assumptions[Risk_Adjustment_Ratio]) -> 0.14 | O8: =_xlfn.XLOOKUP(CF_Gen_1[[#This Row],[ICG]],Assumptions[ICG],Assumptions[PME_Ratio]) -> 0.045 | P8: =_xlfn.XLOOKUP(CF_Gen_1[[#This Row],[ICG]],Assumptions[ICG],Assumptions[ULAE_Ratio]) -> 0.11 | Q8: =_xlfn.XLOOKUP(CF_Gen_1[[#This Row],[ICG]],Assumptions[ICG],Assumptions[Cancellation_Ratio]) -> 0.07 | R8: =_xlfn.XLOOKUP(CF_Gen_1[[#This Row],[ICG]],Assumptions[ICG],Assumptions[Premium_Refund_Ratio]) -> 0.5 | S8: =IF(CF_Gen_1[[#This Row],[Contract]]="RC",_xlfn.XLOOKUP(CF_Gen_1[[#This Row],[ICG]],Assumptions[ICG],Assumptions[NPR_Ratio]),0) -> 0 | T8: =T7*(1-CF_Gen_1[[#This Row],[Cancellation_Ratio]]) -> 0.64699018 | U8: =IF(CF_Gen_1[[#This Row],[Incurred]]<=CF_Gen_1[[#This Row],[Valuation]],CF_Gen_1[[#This Row],[Expected_Premium]],-CF_Gen_1[[#This Row],[Probability_of_Inforce]]*CF_Gen_1[[#This Row],[Premium_Refund_Ratio]]*CF_Gen_1[[#This Row],[Cancellation_Ratio]]*SUM(K8:K$105)) -> -2.6209505e+09 | V8: =IF(CF_Gen_1[[#This Row],[Incurred]]<=CF_Gen_1[[#This Row],[Valuation]],CF_Gen_1[[#This Row],[Expected_Commission]],-CF_Gen_1[[#This Row],[Probability_of_Inforce]]*CF_Gen_1[[#This Row],[Premium_Refund_Ratio]]*CF_Gen_1[[#This Row],[Cancellation_Ratio]]*SUM(L8:L$105)) -> 7.9603216e+08 | W8: =CF_Gen_1[[#This Row],[Expected_Acquisition]] -> 0 | X8: =-CF_Gen_1[[#This Row],[Probability_of_Inforce]]*CF_Gen_1[[#This Row],[Earned_Premium]]*(1-CF_Gen_1[[#This Row],[Cancellation_Ratio]])*CF_Gen_1[[#This Row],[PME_Ratio]]+CF_Gen_1[[#This Row],[ULAE_Ratio]]*CF_Gen_1[[#This Row],[Exp_Claim]] -> -1.4004911e+08 | Y8: =-CF_Gen_1[[#This Row],[Probability_of_Inforce]]*CF_Gen_1[[#This Row],[Earned_Premium]]*(1-CF_Gen_1[[#This Row],[Cancellation_Ratio]])*CF_Gen_1[[#This Row],[Loss_Ratio]] -> -6.2943422e+08 | Z8: =CF_Gen_1[[#This Row],[Exp_Claim]]*CF_Gen_1[[#This Row],[Risk_Adjustment_Ratio]] -> -88120790 | AA8: =IF(CF_Gen_1[[#This Row],[Contract]]="RC",-CF_Gen_1[[#This Row],[NPR_Ratio]]*CF_Gen_1[[#This Row],[Exp_Claim]],0) -> 0 | AB8: =SUMIFS(Actual_CF[Actual_Premium],Actual_CF[ICG],CF_Gen_1[[#This Row],[ICG]],Actual_CF[Incurred],CF_Gen_1[[#This Row],[Incurred]]) -> 0 | AC8: =SUMIFS(Actual_CF[Actual_Commission],Actual_CF[ICG],CF_Gen_1[[#This Row],[ICG]],Actual_CF[Incurred],CF_Gen_1[[#This Row],[Incurred]]) -> 0 | AD8: =SUMIFS(Actual_CF[Actual_Acquisition],Actual_CF[ICG],CF_Gen_1[[#This Row],[ICG]],Actual_CF[Incurred],CF_Gen_1[[#This Row],[Incurred]]) -> 0
A9: =A8 -> #2024#IC-Property | B9: =_xlfn.XLOOKUP(CF_Gen_1[[#This Row],[ICG]],ICG[ICG],ICG[Cohort]) -> 2024 | C9: =_xlfn.XLOOKUP(CF_Gen_1[[#This Row],[ICG]],ICG[ICG],ICG[Portfolio]) -> IC-Property | D9: =_xlfn.XLOOKUP(CF_Gen_1[[#This Row],[ICG]],ICG[ICG],ICG[Contract]) -> IC | E9: =ValuationDate -> 45930 | F9: 8 | G9: =EOMONTH(DATE(YEAR(CF_Gen_1[[#This Row],[Valuation]])-1,12,31),CF_Gen_1[[#This Row],['#Incurred]]*3) -> 46387 | H9: =SUMIFS(Expected_CF[Expected_Premium],Expected_CF[ICG],CF_Gen_1[[#This Row],[ICG]],Expected_CF[Incurred],CF_Gen_1[[#This Row],[Incurred]]) -> 0 | I9: =SUMIFS(Expected_CF[Expected_Commission],Expected_CF[ICG],CF_Gen_1[[#This Row],[ICG]],Expected_CF[Incurred],CF_Gen_1[[#This Row],[Incurred]]) -> 0 | J9: =IF(CF_Gen_1[[#This Row],[Contract]]="IC",SUMIFS(Expected_CF[Expected_Acquisition],Expected_CF[ICG],CF_Gen_1[[#This Row],[ICG]],Expected_CF[Incurred],CF_Gen_1[[#This Row],[Incurred]]),0) -> 0 | K9: =SUMIFS(Earned[Earned_Premium],Earned[ICG],CF_Gen_1[[#This Row],[ICG]],Earned[Incurred],CF_Gen_1[[#This Row],[Incurred]]) -> 2.5853406e+09 | L9: =SUMIFS(Earned[Earned_Commission],Earned[ICG],CF_Gen_1[[#This Row],[ICG]],Earned[Incurred],CF_Gen_1[[#This Row],[Incurred]]) -> -8.0271463e+08 | M9: =_xlfn.XLOOKUP(CF_Gen_1[[#This Row],[ICG]],Assumptions[ICG],Assumptions[Loss_Ratio]) -> 0.4 | N9: =_xlfn.XLOOKUP(CF_Gen_1[[#This Row],[ICG]],Assumptions[ICG],Assumptions[Risk_Adjustment_Ratio]) -> 0.14 | O9: =_xlfn.XLOOKUP(CF_Gen_1[[#This Row],[ICG]],Assumptions[ICG],Assumptions[PME_Ratio]) -> 0.045 | P9: =_xlfn.XLOOKUP(CF_Gen_1[[#This Row],[ICG]],Assumptions[ICG],Assumptions[ULAE_Ratio]) -> 0.11 | Q9: =_xlfn.XLOOKUP(CF_Gen_1[[#This Row],[ICG]],Assumptions[ICG],Assumptions[Cancellation_Ratio]) -> 0.07 | R9: =_xlfn.XLOOKUP(CF_Gen_1[[#This Row],[ICG]],Assumptions[ICG],Assumptions[Premium_Refund_Ratio]) -> 0.5 | S9: =IF(CF_Gen_1[[#This Row],[Contract]]="RC",_xlfn.XLOOKUP(CF_Gen_1[[#This Row],[ICG]],Assumptions[ICG],Assumptions[NPR_Ratio]),0) -> 0 | T9: =T8*(1-CF_Gen_1[[#This Row],[Cancellation_Ratio]]) -> 0.60170087 | U9: =IF(CF_Gen_1[[#This Row],[Incurred]]<=CF_Gen_1[[#This Row],[Valuation]],CF_Gen_1[[#This Row],[Expected_Premium]],-CF_Gen_1[[#This Row],[Probability_of_Inforce]]*CF_Gen_1[[#This Row],[Premium_Refund_Ratio]]*CF_Gen_1[[#This Row],[Cancellation_Ratio]]*SUM(K9:K$105)) -> -2.3824085e+09 | V9: =IF(CF_Gen_1[[#This Row],[Incurred]]<=CF_Gen_1[[#This Row],[Valuation]],CF_Gen_1[[#This Row],[Expected_Commission]],-CF_Gen_1[[#This Row],[Probability_of_Inforce]]*CF_Gen_1[[#This Row],[Premium_Refund_Ratio]]*CF_Gen_1[[#This Row],[Cancellation_Ratio]]*SUM(L9:L$105)) -> 7.2320506e+08 | W9: =CF_Gen_1[[#This Row],[Expected_Acquisition]] -> 0 | X9: =-CF_Gen_1[[#This Row],[Probability_of_Inforce]]*CF_Gen_1[[#This Row],[Earned_Premium]]*(1-CF_Gen_1[[#This Row],[Cancellation_Ratio]])*CF_Gen_1[[#This Row],[PME_Ratio]]+CF_Gen_1[[#This Row],[ULAE_Ratio]]*CF_Gen_1[[#This Row],[Exp_Claim]] -> -1.2875715e+08 | Y9: =-CF_Gen_1[[#This Row],[Probability_of_Inforce]]*CF_Gen_1[[#This Row],[Earned_Premium]]*(1-CF_Gen_1[[#This Row],[Cancellation_Ratio]])*CF_Gen_1[[#This Row],[Loss_Ratio]] -> -5.7868383e+08 | Z9: =CF_Gen_1[[#This Row],[Exp_Claim]]*CF_Gen_1[[#This Row],[Risk_Adjustment_Ratio]] -> -81015737 | AA9: =IF(CF_Gen_1[[#This Row],[Contract]]="RC",-CF_Gen_1[[#This Row],[NPR_Ratio]]*CF_Gen_1[[#This Row],[Exp_Claim]],0) -> 0 | AB9: =SUMIFS(Actual_CF[Actual_Premium],Actual_CF[ICG],CF_Gen_1[[#This Row],[ICG]],Actual_CF[Incurred],CF_Gen_1[[#This Row],[Incurred]]) -> 0 | AC9: =SUMIFS(Actual_CF[Actual_Commission],Actual_CF[ICG],CF_Gen_1[[#This Row],[ICG]],Actual_CF[Incurred],CF_Gen_1[[#This Row],[Incurred]]) -> 0 | AD9: =SUMIFS(Actual_CF[Actual_Acquisition],Actual_CF[ICG],CF_Gen_1[[#This Row],[ICG]],Actual_CF[Incurred],CF_Gen_1[[#This Row],[Incurred]]) -> 0
A10: =A9 -> #2024#IC-Property | B10: =_xlfn.XLOOKUP(CF_Gen_1[[#This Row],[ICG]],ICG[ICG],ICG[Cohort]) -> 2024 | C10: =_xlfn.XLOOKUP(CF_Gen_1[[#This Row],[ICG]],ICG[ICG],ICG[Portfolio]) -> IC-Property | D10: =_xlfn.XLOOKUP(CF_Gen_1[[#This Row],[ICG]],ICG[ICG],ICG[Contract]) -> IC | E10: =ValuationDate -> 45930 | F10: 9 | G10: =EOMONTH(DATE(YEAR(CF_Gen_1[[#This Row],[Valuation]])-1,12,31),CF_Gen_1[[#This Row],['#Incurred]]*3) -> 46477 | H10: =SUMIFS(Expected_CF[Expected_Premium],Expected_CF[ICG],CF_Gen_1[[#This Row],[ICG]],Expected_CF[Incurred],CF_Gen_1[[#This Row],[Incurred]]) -> 0 | I10: =SUMIFS(Expected_CF[Expected_Commission],Expected_CF[ICG],CF_Gen_1[[#This Row],[ICG]],Expected_CF[Incurred],CF_Gen_1[[#This Row],[Incurred]]) -> 0 | J10: =IF(CF_Gen_1[[#This Row],[Contract]]="IC",SUMIFS(Expected_CF[Expected_Acquisition],Expected_CF[ICG],CF_Gen_1[[#This Row],[ICG]],Expected_CF[Incurred],CF_Gen_1[[#This Row],[Incurred]]),0) -> 0 | K10: =SUMIFS(Earned[Earned_Premium],Earned[ICG],CF_Gen_1[[#This Row],[ICG]],Earned[Incurred],CF_Gen_1[[#This Row],[Incurred]]) -> 2.5554523e+09 | L10: =SUMIFS(Earned[Earned_Commission],Earned[ICG],CF_Gen_1[[#This Row],[ICG]],Earned[Incurred],CF_Gen_1[[#This Row],[Incurred]]) -> -7.9321505e+08 | M10: =_xlfn.XLOOKUP(CF_Gen_1[[#This Row],[ICG]],Assumptions[ICG],Assumptions[Loss_Ratio]) -> 0.4 | N10: =_xlfn.XLOOKUP(CF_Gen_1[[#This Row],[ICG]],Assumptions[ICG],Assumptions[Risk_Adjustment_Ratio]) -> 0.14 | O10: =_xlfn.XLOOKUP(CF_Gen_1[[#This Row],[ICG]],Assumptions[ICG],Assumptions[PME_Ratio]) -> 0.045 | P10: =_xlfn.XLOOKUP(CF_Gen_1[[#This Row],[ICG]],Assumptions[ICG],Assumptions[ULAE_Ratio]) -> 0.11 | Q10: =_xlfn.XLOOKUP(CF_Gen_1[[#This Row],[ICG]],Assumptions[ICG],Assumptions[Cancellation_Ratio]) -> 0.07 | R10: =_xlfn.XLOOKUP(CF_Gen_1[[#This Row],[ICG]],Assumptions[ICG],Assumptions[Premium_Refund_Ratio]) -> 0.5 | S10: =IF(CF_Gen_1[[#This Row],[Contract]]="RC",_xlfn.XLOOKUP(CF_Gen_1[[#This Row],[ICG]],Assumptions[ICG],Assumptions[NPR_Ratio]),0) -> 0 | T10: =T9*(1-CF_Gen_1[[#This Row],[Cancellation_Ratio]]) -> 0.55958181 | U10: =IF(CF_Gen_1[[#This Row],[Incurred]]<=CF_Gen_1[[#This Row],[Valuation]],CF_Gen_1[[#This Row],[Expected_Premium]],-CF_Gen_1[[#This Row],[Probability_of_Inforce]]*CF_Gen_1[[#This Row],[Premium_Refund_Ratio]]*CF_Gen_1[[#This Row],[Cancellation_Ratio]]*SUM(K10:K$105)) -> -2.1650051e+09 | V10: =IF(CF_Gen_1[[#This Row],[Incurred]]<=CF_Gen_1[[#This Row],[Valuation]],CF_Gen_1[[#This Row],[Expected_Commission]],-CF_Gen_1[[#This Row],[Probability_of_Inforce]]*CF_Gen_1[[#This Row],[Premium_Refund_Ratio]]*CF_Gen_1[[#This Row],[Cancellation_Ratio]]*SUM(L10:L$105)) -> 6.5685925e+08 | W10: =CF_Gen_1[[#This Row],[Expected_Acquisition]] -> 0 | X10: =-CF_Gen_1[[#This Row],[Probability_of_Inforce]]*CF_Gen_1[[#This Row],[Earned_Premium]]*(1-CF_Gen_1[[#This Row],[Cancellation_Ratio]])*CF_Gen_1[[#This Row],[PME_Ratio]]+CF_Gen_1[[#This Row],[ULAE_Ratio]]*CF_Gen_1[[#This Row],[Exp_Claim]] -> -1.1835983e+08 | Y10: =-CF_Gen_1[[#This Row],[Probability_of_Inforce]]*CF_Gen_1[[#This Row],[Earned_Premium]]*(1-CF_Gen_1[[#This Row],[Cancellation_Ratio]])*CF_Gen_1[[#This Row],[Loss_Ratio]] -> -5.3195428e+08 | Z10: =CF_Gen_1[[#This Row],[Exp_Claim]]*CF_Gen_1[[#This Row],[Risk_Adjustment_Ratio]] -> -74473599 | AA10: =IF(CF_Gen_1[[#This Row],[Contract]]="RC",-CF_Gen_1[[#This Row],[NPR_Ratio]]*CF_Gen_1[[#This Row],[Exp_Claim]],0) -> 0 | AB10: =SUMIFS(Actual_CF[Actual_Premium],Actual_CF[ICG],CF_Gen_1[[#This Row],[ICG]],Actual_CF[Incurred],CF_Gen_1[[#This Row],[Incurred]]) -> 0 | AC10: =SUMIFS(Actual_CF[Actual_Commission],Actual_CF[ICG],CF_Gen_1[[#This Row],[ICG]],Actual_CF[Incurred],CF_Gen_1[[#This Row],[Incurred]]) -> 0 | AD10: =SUMIFS(Actual_CF[Actual_Acquisition],Actual_CF[ICG],CF_Gen_1[[#This Row],[ICG]],Actual_CF[Incurred],CF_Gen_1[[#This Row],[Incurred]]) -> 0
A11: =A10 -> #2024#IC-Property | B11: =_xlfn.XLOOKUP(CF_Gen_1[[#This Row],[ICG]],ICG[ICG],ICG[Cohort]) -> 2024 | C11: =_xlfn.XLOOKUP(CF_Gen_1[[#This Row],[ICG]],ICG[ICG],ICG[Portfolio]) -> IC-Property | D11: =_xlfn.XLOOKUP(CF_Gen_1[[#This Row],[ICG]],ICG[ICG],ICG[Contract]) -> IC | E11: =ValuationDate -> 45930 | F11: 10 | G11: =EOMONTH(DATE(YEAR(CF_Gen_1[[#This Row],[Valuation]])-1,12,31),CF_Gen_1[[#This Row],['#Incurred]]*3) -> 46568 | H11: =SUMIFS(Expected_CF[Expected_Premium],Expected_CF[ICG],CF_Gen_1[[#This Row],[ICG]],Expected_CF[Incurred],CF_Gen_1[[#This Row],[Incurred]]) -> 0 | I11: =SUMIFS(Expected_CF[Expected_Commission],Expected_CF[ICG],CF_Gen_1[[#This Row],[ICG]],Expected_CF[Incurred],CF_Gen_1[[#This Row],[Incurred]]) -> 0 | J11: =IF(CF_Gen_1[[#This Row],[Contract]]="IC",SUMIFS(Expected_CF[Expected_Acquisition],Expected_CF[ICG],CF_Gen_1[[#This Row],[ICG]],Expected_CF[Incurred],CF_Gen_1[[#This Row],[Incurred]]),0) -> 0 | K11: =SUMIFS(Earned[Earned_Premium],Earned[ICG],CF_Gen_1[[#This Row],[ICG]],Earned[Incurred],CF_Gen_1[[#This Row],[Incurred]]) -> 2.525564e+09 | L11: =SUMIFS(Earned[Earned_Commission],Earned[ICG],CF_Gen_1[[#This Row],[ICG]],Earned[Incurred],CF_Gen_1[[#This Row],[Incurred]]) -> -7.8371547e+08 | M11: =_xlfn.XLOOKUP(CF_Gen_1[[#This Row],[ICG]],Assumptions[ICG],Assumptions[Loss_Ratio]) -> 0.4 | N11: =_xlfn.XLOOKUP(CF_Gen_1[[#This Row],[ICG]],Assumptions[ICG],Assumptions[Risk_Adjustment_Ratio]) -> 0.14 | O11: =_xlfn.XLOOKUP(CF_Gen_1[[#This Row],[ICG]],Assumptions[ICG],Assumptions[PME_Ratio]) -> 0.045 | P11: =_xlfn.XLOOKUP(CF_Gen_1[[#This Row],[ICG]],Assumptions[ICG],Assumptions[ULAE_Ratio]) -> 0.11 | Q11: =_xlfn.XLOOKUP(CF_Gen_1[[#This Row],[ICG]],Assumptions[ICG],Assumptions[Cancellation_Ratio]) -> 0.07 | R11: =_xlfn.XLOOKUP(CF_Gen_1[[#This Row],[ICG]],Assumptions[ICG],Assumptions[Premium_Refund_Ratio]) -> 0.5 | S11: =IF(CF_Gen_1[[#This Row],[Contract]]="RC",_xlfn.XLOOKUP(CF_Gen_1[[#This Row],[ICG]],Assumptions[ICG],Assumptions[NPR_Ratio]),0) -> 0 | T11: =T10*(1-CF_Gen_1[[#This Row],[Cancellation_Ratio]]) -> 0.52041108 | U11: =IF(CF_Gen_1[[#This Row],[Incurred]]<=CF_Gen_1[[#This Row],[Valuation]],CF_Gen_1[[#This Row],[Expected_Premium]],-CF_Gen_1[[#This Row],[Probability_of_Inforce]]*CF_Gen_1[[#This Row],[Premium_Refund_Ratio]]*CF_Gen_1[[#This Row],[Cancellation_Ratio]]*SUM(K11:K$105)) -> -1.9669087e+09 | V11: =IF(CF_Gen_1[[#This Row],[Incurred]]<=CF_Gen_1[[#This Row],[Valuation]],CF_Gen_1[[#This Row],[Expected_Commission]],-CF_Gen_1[[#This Row],[Probability_of_Inforce]]*CF_Gen_1[[#This Row],[Premium_Refund_Ratio]]*CF_Gen_1[[#This Row],[Cancellation_Ratio]]*SUM(L11:L$105)) -> 5.9643117e+08 | W11: =CF_Gen_1[[#This Row],[Expected_Acquisition]] -> 0 | X11: =-CF_Gen_1[[#This Row],[Probability_of_Inforce]]*CF_Gen_1[[#This Row],[Earned_Premium]]*(1-CF_Gen_1[[#This Row],[Cancellation_Ratio]])*CF_Gen_1[[#This Row],[PME_Ratio]]+CF_Gen_1[[#This Row],[ULAE_Ratio]]*CF_Gen_1[[#This Row],[Exp_Claim]] -> -1.0878722e+08 | Y11: =-CF_Gen_1[[#This Row],[Probability_of_Inforce]]*CF_Gen_1[[#This Row],[Earned_Premium]]*(1-CF_Gen_1[[#This Row],[Cancellation_Ratio]])*CF_Gen_1[[#This Row],[Loss_Ratio]] -> -4.8893131e+08 | Z11: =CF_Gen_1[[#This Row],[Exp_Claim]]*CF_Gen_1[[#This Row],[Risk_Adjustment_Ratio]] -> -68450383 | AA11: =IF(CF_Gen_1[[#This Row],[Contract]]="RC",-CF_Gen_1[[#This Row],[NPR_Ratio]]*CF_Gen_1[[#This Row],[Exp_Claim]],0) -> 0 | AB11: =SUMIFS(Actual_CF[Actual_Premium],Actual_CF[ICG],CF_Gen_1[[#This Row],[ICG]],Actual_CF[Incurred],CF_Gen_1[[#This Row],[Incurred]]) -> 0 | AC11: =SUMIFS(Actual_CF[Actual_Commission],Actual_CF[ICG],CF_Gen_1[[#This Row],[ICG]],Actual_CF[Incurred],CF_Gen_1[[#This Row],[Incurred]]) -> 0 | AD11: =SUMIFS(Actual_CF[Actual_Acquisition],Actual_CF[ICG],CF_Gen_1[[#This Row],[ICG]],Actual_CF[Incurred],CF_Gen_1[[#This Row],[Incurred]]) -> 0
A12: =A11 -> #2024#IC-Property | B12: =_xlfn.XLOOKUP(CF_Gen_1[[#This Row],[ICG]],ICG[ICG],ICG[Cohort]) -> 2024 | C12: =_xlfn.XLOOKUP(CF_Gen_1[[#This Row],[ICG]],ICG[ICG],ICG[Portfolio]) -> IC-Property | D12: =_xlfn.XLOOKUP(CF_Gen_1[[#This Row],[ICG]],ICG[ICG],ICG[Contract]) -> IC | E12: =ValuationDate -> 45930 | F12: 11 | G12: =EOMONTH(DATE(YEAR(CF_Gen_1[[#This Row],[Valuation]])-1,12,31),CF_Gen_1[[#This Row],['#Incurred]]*3) -> 46660 | H12: =SUMIFS(Expected_CF[Expected_Premium],Expected_CF[ICG],CF_Gen_1[[#This Row],[ICG]],Expected_CF[Incurred],CF_Gen_1[[#This Row],[Incurred]]) -> 0 | I12: =SUMIFS(Expected_CF[Expected_Commission],Expected_CF[ICG],CF_Gen_1[[#This Row],[ICG]],Expected_CF[Incurred],CF_Gen_1[[#This Row],[Incurred]]) -> 0 | J12: =IF(CF_Gen_1[[#This Row],[Contract]]="IC",SUMIFS(Expected_CF[Expected_Acquisition],Expected_CF[ICG],CF_Gen_1[[#This Row],[ICG]],Expected_CF[Incurred],CF_Gen_1[[#This Row],[Incurred]]),0) -> 0 | K12: =SUMIFS(Earned[Earned_Premium],Earned[ICG],CF_Gen_1[[#This Row],[ICG]],Earned[Incurred],CF_Gen_1[[#This Row],[Incurred]]) -> 2.4956756e+09 | L12: =SUMIFS(Earned[Earned_Commission],Earned[ICG],CF_Gen_1[[#This Row],[ICG]],Earned[Incurred],CF_Gen_1[[#This Row],[Incurred]]) -> -7.7421588e+08 | M12: =_xlfn.XLOOKUP(CF_Gen_1[[#This Row],[ICG]],Assumptions[ICG],Assumptions[Loss_Ratio]) -> 0.4 | N12: =_xlfn.XLOOKUP(CF_Gen_1[[#This Row],[ICG]],Assumptions[ICG],Assumptions[Risk_Adjustment_Ratio]) -> 0.14 | O12: =_xlfn.XLOOKUP(CF_Gen_1[[#This Row],[ICG]],Assumptions[ICG],Assumptions[PME_Ratio]) -> 0.045 | P12: =_xlfn.XLOOKUP(CF_Gen_1[[#This Row],[ICG]],Assumptions[ICG],Assumptions[ULAE_Ratio]) -> 0.11 | Q12: =_xlfn.XLOOKUP(CF_Gen_1[[#This Row],[ICG]],Assumptions[ICG],Assumptions[Cancellation_Ratio]) -> 0.07 | R12: =_xlfn.XLOOKUP(CF_Gen_1[[#This Row],[ICG]],Assumptions[ICG],Assumptions[Premium_Refund_Ratio]) -> 0.5 | S12: =IF(CF_Gen_1[[#This Row],[Contract]]="RC",_xlfn.XLOOKUP(CF_Gen_1[[#This Row],[ICG]],Assumptions[ICG],Assumptions[NPR_Ratio]),0) -> 0 | T12: =T11*(1-CF_Gen_1[[#This Row],[Cancellation_Ratio]]) -> 0.48398231 | U12: =IF(CF_Gen_1[[#This Row],[Incurred]]<=CF_Gen_1[[#This Row],[Valuation]],CF_Gen_1[[#This Row],[Expected_Premium]],-CF_Gen_1[[#This Row],[Probability_of_Inforce]]*CF_Gen_1[[#This Row],[Premium_Refund_Ratio]]*CF_Gen_1[[#This Row],[Cancellation_Ratio]]*SUM(K12:K$105)) -> -1.7864436e+09 | V12: =IF(CF_Gen_1[[#This Row],[Incurred]]<=CF_Gen_1[[#This Row],[Valuation]],CF_Gen_1[[#This Row],[Expected_Commission]],-CF_Gen_1[[#This Row],[Probability_of_Inforce]]*CF_Gen_1[[#This Row],[Premium_Refund_Ratio]]*CF_Gen_1[[#This Row],[Cancellation_Ratio]]*SUM(L12:L$105)) -> 5.4140534e+08 | W12: =CF_Gen_1[[#This Row],[Expected_Acquisition]] -> 0 | X12: =-CF_Gen_1[[#This Row],[Probability_of_Inforce]]*CF_Gen_1[[#This Row],[Earned_Premium]]*(1-CF_Gen_1[[#This Row],[Cancellation_Ratio]])*CF_Gen_1[[#This Row],[PME_Ratio]]+CF_Gen_1[[#This Row],[ULAE_Ratio]]*CF_Gen_1[[#This Row],[Exp_Claim]] -> -99974808 | Y12: =-CF_Gen_1[[#This Row],[Probability_of_Inforce]]*CF_Gen_1[[#This Row],[Earned_Premium]]*(1-CF_Gen_1[[#This Row],[Cancellation_Ratio]])*CF_Gen_1[[#This Row],[Loss_Ratio]] -> -4.4932498e+08 | Z12: =CF_Gen_1[[#This Row],[Exp_Claim]]*CF_Gen_1[[#This Row],[Risk_Adjustment_Ratio]] -> -62905497 | AA12: =IF(CF_Gen_1[[#This Row],[Contract]]="RC",-CF_Gen_1[[#This Row],[NPR_Ratio]]*CF_Gen_1[[#This Row],[Exp_Claim]],0) -> 0 | AB12: =SUMIFS(Actual_CF[Actual_Premium],Actual_CF[ICG],CF_Gen_1[[#This Row],[ICG]],Actual_CF[Incurred],CF_Gen_1[[#This Row],[Incurred]]) -> 0 | AC12: =SUMIFS(Actual_CF[Actual_Commission],Actual_CF[ICG],CF_Gen_1[[#This Row],[ICG]],Actual_CF[Incurred],CF_Gen_1[[#This Row],[Incurred]]) -> 0 | AD12: =SUMIFS(Actual_CF[Actual_Acquisition],Actual_CF[ICG],CF_Gen_1[[#This Row],[ICG]],Actual_CF[Incurred],CF_Gen_1[[#This Row],[Incurred]]) -> 0
A13: =A12 -> #2024#IC-Property | B13: =_xlfn.XLOOKUP(CF_Gen_1[[#This Row],[ICG]],ICG[ICG],ICG[Cohort]) -> 2024 | C13: =_xlfn.XLOOKUP(CF_Gen_1[[#This Row],[ICG]],ICG[ICG],ICG[Portfolio]) -> IC-Property | D13: =_xlfn.XLOOKUP(CF_Gen_1[[#This Row],[ICG]],ICG[ICG],ICG[Contract]) -> IC | E13: =ValuationDate -> 45930 | F13: 12 | G13: =EOMONTH(DATE(YEAR(CF_Gen_1[[#This Row],[Valuation]])-1,12,31),CF_Gen_1[[#This Row],['#Incurred]]*3) -> 46752 | H13: =SUMIFS(Expected_CF[Expected_Premium],Expected_CF[ICG],CF_Gen_1[[#This Row],[ICG]],Expected_CF[Incurred],CF_Gen_1[[#This Row],[Incurred]]) -> 0 | I13: =SUMIFS(Expected_CF[Expected_Commission],Expected_CF[ICG],CF_Gen_1[[#This Row],[ICG]],Expected_CF[Incurred],CF_Gen_1[[#This Row],[Incurred]]) -> 0 | J13: =IF(CF_Gen_1[[#This Row],[Contract]]="IC",SUMIFS(Expected_CF[Expected_Acquisition],Expected_CF[ICG],CF_Gen_1[[#This Row],[ICG]],Expected_CF[Incurred],CF_Gen_1[[#This Row],[Incurred]]),0) -> 0 | K13: =SUMIFS(Earned[Earned_Premium],Earned[ICG],CF_Gen_1[[#This Row],[ICG]],Earned[Incurred],CF_Gen_1[[#This Row],[Incurred]]) -> 2.4657873e+09 | L13: =SUMIFS(Earned[Earned_Commission],Earned[ICG],CF_Gen_1[[#This Row],[ICG]],Earned[Incurred],CF_Gen_1[[#This Row],[Incurred]]) -> -7.647163e+08 | M13: =_xlfn.XLOOKUP(CF_Gen_1[[#This Row],[ICG]],Assumptions[ICG],Assumptions[Loss_Ratio]) -> 0.4 | N13: =_xlfn.XLOOKUP(CF_Gen_1[[#This Row],[ICG]],Assumptions[ICG],Assumptions[Risk_Adjustment_Ratio]) -> 0.14 | O13: =_xlfn.XLOOKUP(CF_Gen_1[[#This Row],[ICG]],Assumptions[ICG],Assumptions[PME_Ratio]) -> 0.045 | P13: =_xlfn.XLOOKUP(CF_Gen_1[[#This Row],[ICG]],Assumptions[ICG],Assumptions[ULAE_Ratio]) -> 0.11 | Q13: =_xlfn.XLOOKUP(CF_Gen_1[[#This Row],[ICG]],Assumptions[ICG],Assumptions[Cancellation_Ratio]) -> 0.07 | R13: =_xlfn.XLOOKUP(CF_Gen_1[[#This Row],[ICG]],Assumptions[ICG],Assumptions[Premium_Refund_Ratio]) -> 0.5 | S13: =IF(CF_Gen_1[[#This Row],[Contract]]="RC",_xlfn.XLOOKUP(CF_Gen_1[[#This Row],[ICG]],Assumptions[ICG],Assumptions[NPR_Ratio]),0) -> 0 | T13: =T12*(1-CF_Gen_1[[#This Row],[Cancellation_Ratio]]) -> 0.45010355 | U13: =IF(CF_Gen_1[[#This Row],[Incurred]]<=CF_Gen_1[[#This Row],[Valuation]],CF_Gen_1[[#This Row],[Expected_Premium]],-CF_Gen_1[[#This Row],[Probability_of_Inforce]]*CF_Gen_1[[#This Row],[Premium_Refund_Ratio]]*CF_Gen_1[[#This Row],[Cancellation_Ratio]]*SUM(K13:K$105)) -> -1.6220766e+09 | V13: =IF(CF_Gen_1[[#This Row],[Incurred]]<=CF_Gen_1[[#This Row],[Valuation]],CF_Gen_1[[#This Row],[Expected_Commission]],-CF_Gen_1[[#This Row],[Probability_of_Inforce]]*CF_Gen_1[[#This Row],[Premium_Refund_Ratio]]*CF_Gen_1[[#This Row],[Cancellation_Ratio]]*SUM(L13:L$105)) -> 4.9131026e+08 | W13: =CF_Gen_1[[#This Row],[Expected_Acquisition]] -> 0 | X13: =-CF_Gen_1[[#This Row],[Probability_of_Inforce]]*CF_Gen_1[[#This Row],[Earned_Premium]]*(1-CF_Gen_1[[#This Row],[Cancellation_Ratio]])*CF_Gen_1[[#This Row],[PME_Ratio]]+CF_Gen_1[[#This Row],[ULAE_Ratio]]*CF_Gen_1[[#This Row],[Exp_Claim]] -> -91863080 | Y13: =-CF_Gen_1[[#This Row],[Probability_of_Inforce]]*CF_Gen_1[[#This Row],[Earned_Premium]]*(1-CF_Gen_1[[#This Row],[Cancellation_Ratio]])*CF_Gen_1[[#This Row],[Loss_Ratio]] -> -4.1286777e+08 | Z13: =CF_Gen_1[[#This Row],[Exp_Claim]]*CF_Gen_1[[#This Row],[Risk_Adjustment_Ratio]] -> -57801488 | AA13: =IF(CF_Gen_1[[#This Row],[Contract]]="RC",-CF_Gen_1[[#This Row],[NPR_Ratio]]*CF_Gen_1[[#This Row],[Exp_Claim]],0) -> 0 | AB13: =SUMIFS(Actual_CF[Actual_Premium],Actual_CF[ICG],CF_Gen_1[[#This Row],[ICG]],Actual_CF[Incurred],CF_Gen_1[[#This Row],[Incurred]]) -> 0 | AC13: =SUMIFS(Actual_CF[Actual_Commission],Actual_CF[ICG],CF_Gen_1[[#This Row],[ICG]],Actual_CF[Incurred],CF_Gen_1[[#This Row],[Incurred]]) -> 0 | AD13: =SUMIFS(Actual_CF[Actual_Acquisition],Actual_CF[ICG],CF_Gen_1[[#This Row],[ICG]],Actual_CF[Incurred],CF_Gen_1[[#This Row],[Incurred]]) -> 0
A14: =A13 -> #2024#IC-Property | B14: =_xlfn.XLOOKUP(CF_Gen_1[[#This Row],[ICG]],ICG[ICG],ICG[Cohort]) -> 2024 | C14: =_xlfn.XLOOKUP(CF_Gen_1[[#This Row],[ICG]],ICG[ICG],ICG[Portfolio]) -> IC-Property | D14: =_xlfn.XLOOKUP(CF_Gen_1[[#This Row],[ICG]],ICG[ICG],ICG[Contract]) -> IC | E14: =ValuationDate -> 45930 | F14: 13 | G14: =EOMONTH(DATE(YEAR(CF_Gen_1[[#This Row],[Valuation]])-1,12,31),CF_Gen_1[[#This Row],['#Incurred]]*3) -> 46843 | H14: =SUMIFS(Expected_CF[Expected_Premium],Expected_CF[ICG],CF_Gen_1[[#This Row],[ICG]],Expected_CF[Incurred],CF_Gen_1[[#This Row],[Incurred]]) -> 0 | I14: =SUMIFS(Expected_CF[Expected_Commission],Expected_CF[ICG],CF_Gen_1[[#This Row],[ICG]],Expected_CF[Incurred],CF_Gen_1[[#This Row],[Incurred]]) -> 0 | J14: =IF(CF_Gen_1[[#This Row],[Contract]]="IC",SUMIFS(Expected_CF[Expected_Acquisition],Expected_CF[ICG],CF_Gen_1[[#This Row],[ICG]],Expected_CF[Incurred],CF_Gen_1[[#This Row],[Incurred]]),0) -> 0 | K14: =SUMIFS(Earned[Earned_Premium],Earned[ICG],CF_Gen_1[[#This Row],[ICG]],Earned[Incurred],CF_Gen_1[[#This Row],[Incurred]]) -> 2.435899e+09 | L14: =SUMIFS(Earned[Earned_Commission],Earned[ICG],CF_Gen_1[[#This Row],[ICG]],Earned[Incurred],CF_Gen_1[[#This Row],[Incurred]]) -> -7.5521672e+08 | M14: =_xlfn.XLOOKUP(CF_Gen_1[[#This Row],[ICG]],Assumptions[ICG],Assumptions[Loss_Ratio]) -> 0.4 | N14: =_xlfn.XLOOKUP(CF_Gen_1[[#This Row],[ICG]],Assumptions[ICG],Assumptions[Risk_Adjustment_Ratio]) -> 0.14 | O14: =_xlfn.XLOOKUP(CF_Gen_1[[#This Row],[ICG]],Assumptions[ICG],Assumptions[PME_Ratio]) -> 0.045 | P14: =_xlfn.XLOOKUP(CF_Gen_1[[#This Row],[ICG]],Assumptions[ICG],Assumptions[ULAE_Ratio]) -> 0.11 | Q14: =_xlfn.XLOOKUP(CF_Gen_1[[#This Row],[ICG]],Assumptions[ICG],Assumptions[Cancellation_Ratio]) -> 0.07 | R14: =_xlfn.XLOOKUP(CF_Gen_1[[#This Row],[ICG]],Assumptions[ICG],Assumptions[Premium_Refund_Ratio]) -> 0.5 | S14: =IF(CF_Gen_1[[#This Row],[Contract]]="RC",_xlfn.XLOOKUP(CF_Gen_1[[#This Row],[ICG]],Assumptions[ICG],Assumptions[NPR_Ratio]),0) -> 0 | T14: =T13*(1-CF_Gen_1[[#This Row],[Cancellation_Ratio]]) -> 0.4185963 | U14: =IF(CF_Gen_1[[#This Row],[Incurred]]<=CF_Gen_1[[#This Row],[Valuation]],CF_Gen_1[[#This Row],[Expected_Premium]],-CF_Gen_1[[#This Row],[Probability_of_Inforce]]*CF_Gen_1[[#This Row],[Premium_Refund_Ratio]]*CF_Gen_1[[#This Row],[Cancellation_Ratio]]*SUM(K14:K$105)) -> -1.4724053e+09 | V14: =IF(CF_Gen_1[[#This Row],[Incurred]]<=CF_Gen_1[[#This Row],[Valuation]],CF_Gen_1[[#This Row],[Expected_Commission]],-CF_Gen_1[[#This Row],[Probability_of_Inforce]]*CF_Gen_1[[#This Row],[Premium_Refund_Ratio]]*CF_Gen_1[[#This Row],[Cancellation_Ratio]]*SUM(L14:L$105)) -> 4.4571478e+08 | W14: =CF_Gen_1[[#This Row],[Expected_Acquisition]] -> 0 | X14: =-CF_Gen_1[[#This Row],[Probability_of_Inforce]]*CF_Gen_1[[#This Row],[Earned_Premium]]*(1-CF_Gen_1[[#This Row],[Cancellation_Ratio]])*CF_Gen_1[[#This Row],[PME_Ratio]]+CF_Gen_1[[#This Row],[ULAE_Ratio]]*CF_Gen_1[[#This Row],[Exp_Claim]] -> -84397117 | Y14: =-CF_Gen_1[[#This Row],[Probability_of_Inforce]]*CF_Gen_1[[#This Row],[Earned_Premium]]*(1-CF_Gen_1[[#This Row],[Cancellation_Ratio]])*CF_Gen_1[[#This Row],[Loss_Ratio]] -> -3.7931288e+08 | Z14: =CF_Gen_1[[#This Row],[Exp_Claim]]*CF_Gen_1[[#This Row],[Risk_Adjustment_Ratio]] -> -53103804 | AA14: =IF(CF_Gen_1[[#This Row],[Contract]]="RC",-CF_Gen_1[[#This Row],[NPR_Ratio]]*CF_Gen_1[[#This Row],[Exp_Claim]],0) -> 0 | AB14: =SUMIFS(Actual_CF[Actual_Premium],Actual_CF[ICG],CF_Gen_1[[#This Row],[ICG]],Actual_CF[Incurred],CF_Gen_1[[#This Row],[Incurred]]) -> 0 | AC14: =SUMIFS(Actual_CF[Actual_Commission],Actual_CF[ICG],CF_Gen_1[[#This Row],[ICG]],Actual_CF[Incurred],CF_Gen_1[[#This Row],[Incurred]]) -> 0 | AD14: =SUMIFS(Actual_CF[Actual_Acquisition],Actual_CF[ICG],CF_Gen_1[[#This Row],[ICG]],Actual_CF[Incurred],CF_Gen_1[[#This Row],[Incurred]]) -> 0
... A105: =A104 -> #2024#IC-Property | B105: =_xlfn.XLOOKUP(CF_Gen_1[[#This Row],[ICG]],ICG[ICG],ICG[Cohort]) -> 2024 | C105: =_xlfn.XLOOKUP(CF_Gen_1[[#This Row],[ICG]],ICG[ICG],ICG[Portfolio]) -> IC-Property | D105: =_xlfn.XLOOKUP(CF_Gen_1[[#This Row],[ICG]],ICG[ICG],ICG[Contract]) -> IC | E105: =ValuationDate -> 45930 | F105: 104 | G105: =EOMONTH(DATE(YEAR(CF_Gen_1[[#This Row],[Valuation]])-1,12,31),CF_Gen_1[[#This Row],['#Incurred]]*3) -> 55153 | H105: =SUMIFS(Expected_CF[Expected_Premium],Expected_CF[ICG],CF_Gen_1[[#This Row],[ICG]],Expected_CF[Incurred],CF_Gen_1[[#This Row],[Incurred]]) -> 0 | I105: =SUMIFS(Expected_CF[Expected_Commission],Expected_CF[ICG],CF_Gen_1[[#This Row],[ICG]],Expected_CF[Incurred],CF_Gen_1[[#This Row],[Incurred]]) -> 0 | J105: =IF(CF_Gen_1[[#This Row],[Contract]]="IC",SUMIFS(Expected_CF[Expected_Acquisition],Expected_CF[ICG],CF_Gen_1[[#This Row],[ICG]],Expected_CF[Incurred],CF_Gen_1[[#This Row],[Incurred]]),0) -> 0 | K105: =SUMIFS(Earned[Earned_Premium],Earned[ICG],CF_Gen_1[[#This Row],[ICG]],Earned[Incurred],CF_Gen_1[[#This Row],[Incurred]]) -> 0 | L105: =SUMIFS(Earned[Earned_Commission],Earned[ICG],CF_Gen_1[[#This Row],[ICG]],Earned[Incurred],CF_Gen_1[[#This Row],[Incurred]]) -> 0 | M105: =_xlfn.XLOOKUP(CF_Gen_1[[#This Row],[ICG]],Assumptions[ICG],Assumptions[Loss_Ratio]) -> 0.4 | N105: =_xlfn.XLOOKUP(CF_Gen_1[[#This Row],[ICG]],Assumptions[ICG],Assumptions[Risk_Adjustment_Ratio]) -> 0.14 | O105: =_xlfn.XLOOKUP(CF_Gen_1[[#This Row],[ICG]],Assumptions[ICG],Assumptions[PME_Ratio]) -> 0.045 | P105: =_xlfn.XLOOKUP(CF_Gen_1[[#This Row],[ICG]],Assumptions[ICG],Assumptions[ULAE_Ratio]) -> 0.11 | Q105: =_xlfn.XLOOKUP(CF_Gen_1[[#This Row],[ICG]],Assumptions[ICG],Assumptions[Cancellation_Ratio]) -> 0.07 | R105: =_xlfn.XLOOKUP(CF_Gen_1[[#This Row],[ICG]],Assumptions[ICG],Assumptions[Premium_Refund_Ratio]) -> 0.5 | S105: =IF(CF_Gen_1[[#This Row],[Contract]]="RC",_xlfn.XLOOKUP(CF_Gen_1[[#This Row],[ICG]],Assumptions[ICG],Assumptions[NPR_Ratio]),0) -> 0 | T105: =T104*(1-CF_Gen_1[[#This Row],[Cancellation_Ratio]]) -> 0.00056720977 | U105: =IF(CF_Gen_1[[#This Row],[Incurred]]<=CF_Gen_1[[#This Row],[Valuation]],CF_Gen_1[[#This Row],[Expected_Premium]],-CF_Gen_1[[#This Row],[Probability_of_Inforce]]*CF_Gen_1[[#This Row],[Premium_Refund_Ratio]]*CF_Gen_1[[#This Row],[Cancellation_Ratio]]*SUM(K105:K$105)) -> 0 | V105: =IF(CF_Gen_1[[#This Row],[Incurred]]<=CF_Gen_1[[#This Row],[Valuation]],CF_Gen_1[[#This Row],[Expected_Commission]],-CF_Gen_1[[#This Row],[Probability_of_Inforce]]*CF_Gen_1[[#This Row],[Premium_Refund_Ratio]]*CF_Gen_1[[#This Row],[Cancellation_Ratio]]*SUM(L105:L$105)) -> 0 | W105: =CF_Gen_1[[#This Row],[Expected_Acquisition]] -> 0 | X105: =-CF_Gen_1[[#This Row],[Probability_of_Inforce]]*CF_Gen_1[[#This Row],[Earned_Premium]]*(1-CF_Gen_1[[#This Row],[Cancellation_Ratio]])*CF_Gen_1[[#This Row],[PME_Ratio]]+CF_Gen_1[[#This Row],[ULAE_Ratio]]*CF_Gen_1[[#This Row],[Exp_Claim]] -> 0 | Y105: =-CF_Gen_1[[#This Row],[Probability_of_Inforce]]*CF_Gen_1[[#This Row],[Earned_Premium]]*(1-CF_Gen_1[[#This Row],[Cancellation_Ratio]])*CF_Gen_1[[#This Row],[Loss_Ratio]] -> 0 | Z105: =CF_Gen_1[[#This Row],[Exp_Claim]]*CF_Gen_1[[#This Row],[Risk_Adjustment_Ratio]] -> 0 | AA105: =IF(CF_Gen_1[[#This Row],[Contract]]="RC",-CF_Gen_1[[#This Row],[NPR_Ratio]]*CF_Gen_1[[#This Row],[Exp_Claim]],0) -> 0 | AB105: =SUMIFS(Actual_CF[Actual_Premium],Actual_CF[ICG],CF_Gen_1[[#This Row],[ICG]],Actual_CF[Incurred],CF_Gen_1[[#This Row],[Incurred]]) -> 0 | AC105: =SUMIFS(Actual_CF[Actual_Commission],Actual_CF[ICG],CF_Gen_1[[#This Row],[ICG]],Actual_CF[Incurred],CF_Gen_1[[#This Row],[Incurred]]) -> 0 | AD105: =SUMIFS(Actual_CF[Actual_Acquisition],Actual_CF[ICG],CF_Gen_1[[#This Row],[ICG]],Actual_CF[Incurred],CF_Gen_1[[#This Row],[Incurred]]) -> 0

Sheet CF_Gen_2
A1: ICG | B1: Cohort | C1: Portfolio | D1: Contract | E1: Valuation | F1: #Incurred | G1: Incurred | H1: Expected_Premium | I1: Expected_Commission | J1: Expected_Acquisition | K1: Earned_Premium | L1: Earned_Commission | M1: Loss_Ratio | N1: Risk_Adjustment_Ratio | O1: PME_Ratio | P1: ULAE_Ratio | Q1: Cancellation_Ratio | R1: Premium_Refund_Ratio | S1: NPR_Ratio | T1: Probability_of_Inforce | U1: Exp_Premium | V1: Exp_Commission | W1: Exp_Acquisition | X1: Exp_Expense | Y1: Exp_Claim | Z1: Exp_RA | AA1: Exp_NPR | AB1: Actual_Premium | AC1: Actual_Commission | AD1: Actual_Acquisition
